<sdf version='1.6'>
  <world name='default'>
    <model name='ground_plane'>
      <static>1</static>
      <link name='link'>
        <collision name='collision'>
          <geometry>
            <plane>
              <normal>0 0 1</normal>
              <size>100 100</size>
            </plane>
          </geometry>
          <surface>
            <friction>
              <ode>
                <mu>100</mu>
                <mu2>50</mu2>
              </ode>
              <torsional>
                <ode/>
              </torsional>
            </friction>
            <contact>
              <ode/>
            </contact>
            <bounce/>
          </surface>
          <max_contacts>10</max_contacts>
        </collision>
        <visual name='visual'>
          <cast_shadows>0</cast_shadows>
          <geometry>
            <plane>
              <normal>0 0 1</normal>
              <size>100 100</size>
            </plane>
          </geometry>
          <material>
            <script>
              <uri>file://media/materials/scripts/gazebo.material</uri>
              <name>Gazebo/Grey</name>
            </script>
          </material>
        </visual>
        <self_collide>0</self_collide>
        <kinematic>0</kinematic>
        <gravity>1</gravity>
      </link>
    </model>
    <light name='sun' type='directional'>
      <cast_shadows>1</cast_shadows>
      <pose frame=''>0 0 10 0 -0 0</pose>
      <diffuse>0.8 0.8 0.8 1</diffuse>
      <specular>0.1 0.1 0.1 1</specular>
      <attenuation>
        <range>1000</range>
        <constant>0.9</constant>
        <linear>0.01</linear>
        <quadratic>0.001</quadratic>
      </attenuation>
      <direction>-0.5 0.5 -1</direction>
    </light>
    <gui fullscreen='0'>
      <camera name='user_camera'>
        <pose frame=''>51.7722 6.73085 34.5788 0 0.643643 2.94419</pose>
        <view_controller>orbit</view_controller>
        <projection_type>perspective</projection_type>
      </camera>
    </gui>
    <gravity>0 0 -9.8</gravity>
    <magnetic_field>6e-06 2.3e-05 -4.2e-05</magnetic_field>
    <atmosphere type='adiabatic'/>
    <physics name='default_physics' default='0' type='ode'>
      <max_step_size>0.001</max_step_size>
      <real_time_factor>1</real_time_factor>
      <real_time_update_rate>1000</real_time_update_rate>
    </physics>
    <scene>
      <ambient>0.4 0.4 0.4 1</ambient>
      <background>0.7 0.7 0.7 1</background>
      <shadows>1</shadows>
    </scene>
    <spherical_coordinates>
      <surface_model>EARTH_WGS84</surface_model>
      <latitude_deg>0</latitude_deg>
      <longitude_deg>0</longitude_deg>
      <elevation>0</elevation>
      <heading_deg>0</heading_deg>
    </spherical_coordinates>
    <model name='swerve'>
      <link name='odom'>
        <pose frame=''>0 0 0 0 -0 0</pose>
        <inertial>
          <pose frame=''>-0.01267 0 0.169932 0 -0 0</pose>
          <mass>7.0062</mass>
          <inertia>
            <ixx>0.532804</ixx>
            <ixy>-9.64381e-07</ixy>
            <ixz>-1.34145e-05</ixz>
            <iyy>0.270259</iyy>
            <iyz>4.92742e-11</iyz>
            <izz>0.263485</izz>
          </inertia>
        </inertial>
        <collision name='odom_fixed_joint_lump__swerve_body_collision'>
          <pose frame=''>0 0 0.17 0 0 -1.5708</pose>
          <geometry>
            <mesh>
              <scale>1 1 1</scale>
              <uri>/home/swerve/Swerve/swerve_ws/src/swerve/swerve_description/meshes/chassis.stl</uri>
            </mesh>
          </geometry>
          <max_contacts>10</max_contacts>
          <surface>
            <contact>
              <ode/>
            </contact>
            <bounce/>
            <friction>
              <torsional>
                <ode/>
              </torsional>
              <ode/>
            </friction>
          </surface>
        </collision>
        <visual name='odom_fixed_joint_lump__swerve_body_visual'>
          <pose frame=''>0 0 0.17 0 0 -1.5708</pose>
          <geometry>
            <mesh>
              <scale>1 1 1</scale>
              <uri>/home/swerve/Swerve/swerve_ws/src/swerve/swerve_description/meshes/chassis.stl</uri>
            </mesh>
          </geometry>
        </visual>
        <visual name='odom_fixed_joint_lump__laser_visual_1'>
          <pose frame=''>0.2 -1e-06 0.233 0 -0 0</pose>
          <geometry>
            <mesh>
              <scale>1 1 1</scale>
              <uri>/opt/ros/kinetic/share/sick_tim/meshes/sick_tim551.stl</uri>
            </mesh>
          </geometry>
          <material>
            <script>
              <uri>__default__</uri>
              <name>__default__</name>
            </script>
          </material>
        </visual>
        <visual name='odom_fixed_joint_lump__zed_center_visual_2'>
          <pose frame=''>0.18 -1e-06 0.28 0 -0 0</pose>
          <geometry>
            <mesh>
              <scale>1 1 1</scale>
              <uri>/home/swerve/Swerve/swerve_ws/src/swerve/swerve_description/meshes/ZED.stl</uri>
            </mesh>
          </geometry>
        </visual>
        <visual name='odom_fixed_joint_lump__zed_left_camera_visual_3'>
          <pose frame=''>0.18 0.059999 0.28 -3.14159 1.57079 -3.14159</pose>
          <geometry>
            <cylinder>
              <length>0.031</length>
              <radius>0.007</radius>
            </cylinder>
          </geometry>
        </visual>
        <visual name='odom_fixed_joint_lump__zed_right_camera_visual_4'>
          <pose frame=''>0.18 -0.060001 0.28 -3.14159 1.57079 -3.14159</pose>
          <geometry>
            <cylinder>
              <length>0.031</length>
              <radius>0.007</radius>
            </cylinder>
          </geometry>
        </visual>
        <gravity>1</gravity>
        <velocity_decay/>
        <self_collide>0</self_collide>
        <sensor name='laser' type='ray'>
          <always_on>1</always_on>
          <visualize>1</visualize>
          <update_rate>15</update_rate>
          <ray>
            <scan>
              <horizontal>
                <samples>810</samples>
                <resolution>1</resolution>
                <min_angle>-2.35619</min_angle>
                <max_angle>2.35619</max_angle>
              </horizontal>
              <vertical>
                <samples>1</samples>
                <min_angle>0</min_angle>
                <max_angle>0</max_angle>
              </vertical>
            </scan>
            <range>
              <min>0.1</min>
              <max>20</max>
              <resolution>0.01</resolution>
            </range>
            <noise>
              <type>gaussian</type>
              <mean>0</mean>
              <stddev>0.00667</stddev>
            </noise>
          </ray>
          <plugin name='gazebo_ros_head_hokuyo_controller' filename='libgazebo_ros_laser.so'>
            <topicName>scan</topicName>
            <frameName>laser</frameName>
            <robotNamespace>/</robotNamespace>
          </plugin>
          <pose frame=''>0.2 -1e-06 0.233 0 -0 0</pose>
        </sensor>
        <kinematic>0</kinematic>
      </link>
      <link name='swerve_FS_link'>
        <pose frame=''>0.381 -1e-06 0.17 1.5708 0 -1.5708</pose>
        <inertial>
          <pose frame=''>-0 -0.062713 0 0 -0 0</pose>
          <mass>0.449039</mass>
          <inertia>
            <ixx>0.0010313</ixx>
            <ixy>1.377e-13</ixy>
            <ixz>4.6213e-21</ixz>
            <iyy>0.00038801</iyy>
            <iyz>-9.7714e-21</iyz>
            <izz>0.001103</izz>
          </inertia>
        </inertial>
        <collision name='swerve_FS_link_collision'>
          <pose frame=''>0 0 0 0 -0 0</pose>
          <geometry>
            <mesh>
              <scale>1 1 1</scale>
              <uri>/home/swerve/Swerve/swerve_ws/src/swerve/swerve_description/meshes/swivel.stl</uri>
            </mesh>
          </geometry>
          <max_contacts>10</max_contacts>
          <surface>
            <contact>
              <ode/>
            </contact>
            <bounce/>
            <friction>
              <torsional>
                <ode/>
              </torsional>
              <ode/>
            </friction>
          </surface>
        </collision>
        <visual name='swerve_FS_link_visual'>
          <pose frame=''>0 0 0 0 -0 0</pose>
          <geometry>
            <mesh>
              <scale>1 1 1</scale>
              <uri>/home/swerve/Swerve/swerve_ws/src/swerve/swerve_description/meshes/swivel.stl</uri>
            </mesh>
          </geometry>
        </visual>
        <self_collide>0</self_collide>
        <kinematic>0</kinematic>
        <gravity>1</gravity>
      </link>
      <joint name='swerve_joint_FS' type='revolute'>
        <child>swerve_FS_link</child>
        <parent>odom</parent>
        <axis>
          <xyz>4e-06 0 -1</xyz>
          <limit>
            <lower>-1e+16</lower>
            <upper>1e+16</upper>
          </limit>
          <dynamics>
            <spring_reference>0</spring_reference>
            <spring_stiffness>0</spring_stiffness>
          </dynamics>
          <use_parent_model_frame>1</use_parent_model_frame>
        </axis>
      </joint>
      <link name='swerve_FW_link'>
        <pose frame=''>0.381 -1e-06 0.043 1.5708 0 -1.5708</pose>
        <inertial>
          <pose frame=''>-0 0 0 0 -0 0</pose>
          <mass>0.15026</mass>
          <inertia>
            <ixx>0.00016727</ixx>
            <ixy>-4.9394e-22</ixy>
            <ixz>-2.3462e-22</ixz>
            <iyy>9.626e-05</iyy>
            <iyz>-1.4682e-20</iyz>
            <izz>9.626e-05</izz>
          </inertia>
        </inertial>
        <collision name='swerve_FW_link_collision'>
          <pose frame=''>0 0 0 0 -0 0</pose>
          <geometry>
            <mesh>
              <scale>1 1 1</scale>
              <uri>/home/swerve/Swerve/swerve_ws/src/swerve/swerve_description/meshes/wheel.stl</uri>
            </mesh>
          </geometry>
          <max_contacts>10</max_contacts>
          <surface>
            <contact>
              <ode/>
            </contact>
            <bounce/>
            <friction>
              <torsional>
                <ode/>
              </torsional>
              <ode/>
            </friction>
          </surface>
        </collision>
        <visual name='swerve_FW_link_visual'>
          <pose frame=''>0 0 0 0 -0 0</pose>
          <geometry>
            <mesh>
              <scale>1 1 1</scale>
              <uri>/home/swerve/Swerve/swerve_ws/src/swerve/swerve_description/meshes/wheel.stl</uri>
            </mesh>
          </geometry>
        </visual>
        <self_collide>0</self_collide>
        <kinematic>0</kinematic>
        <gravity>1</gravity>
      </link>
      <joint name='swerve_joint_FW' type='revolute'>
        <child>swerve_FW_link</child>
        <parent>swerve_FS_link</parent>
        <axis>
          <xyz>4e-06 1 0</xyz>
          <limit>
            <lower>-1e+16</lower>
            <upper>1e+16</upper>
          </limit>
          <dynamics>
            <spring_reference>0</spring_reference>
            <spring_stiffness>0</spring_stiffness>
          </dynamics>
          <use_parent_model_frame>1</use_parent_model_frame>
        </axis>
      </joint>
      <link name='swerve_LS_link'>
        <pose frame=''>-0.190499 0.329961 0.17 1.5708 0 -1.5708</pose>
        <inertial>
          <pose frame=''>-0 -0.062713 0 0 -0 0</pose>
          <mass>0.449039</mass>
          <inertia>
            <ixx>0.0010313</ixx>
            <ixy>1.377e-13</ixy>
            <ixz>1.6475e-20</ixz>
            <iyy>0.00038801</iyy>
            <iyz>2.1123e-20</iyz>
            <izz>0.001103</izz>
          </inertia>
        </inertial>
        <collision name='swerve_LS_link_collision'>
          <pose frame=''>0 0 0 0 -0 0</pose>
          <geometry>
            <mesh>
              <scale>1 1 1</scale>
              <uri>/home/swerve/Swerve/swerve_ws/src/swerve/swerve_description/meshes/swivel.stl</uri>
            </mesh>
          </geometry>
          <max_contacts>10</max_contacts>
          <surface>
            <contact>
              <ode/>
            </contact>
            <bounce/>
            <friction>
              <torsional>
                <ode/>
              </torsional>
              <ode/>
            </friction>
          </surface>
        </collision>
        <visual name='swerve_LS_link_visual'>
          <pose frame=''>0 0 0 0 -0 0</pose>
          <geometry>
            <mesh>
              <scale>1 1 1</scale>
              <uri>/home/swerve/Swerve/swerve_ws/src/swerve/swerve_description/meshes/swivel.stl</uri>
            </mesh>
          </geometry>
        </visual>
        <self_collide>0</self_collide>
        <kinematic>0</kinematic>
        <gravity>1</gravity>
      </link>
      <joint name='swerve_joint_LS' type='revolute'>
        <child>swerve_LS_link</child>
        <parent>odom</parent>
        <axis>
          <xyz>4e-06 0 -1</xyz>
          <limit>
            <lower>-1e+16</lower>
            <upper>1e+16</upper>
          </limit>
          <dynamics>
            <spring_reference>0</spring_reference>
            <spring_stiffness>0</spring_stiffness>
          </dynamics>
          <use_parent_model_frame>1</use_parent_model_frame>
        </axis>
      </joint>
      <link name='swerve_LW_link'>
        <pose frame=''>-0.190498 0.329961 0.043 1.5708 0 -1.5708</pose>
        <inertial>
          <pose frame=''>0 0 0 0 -0 0</pose>
          <mass>0.15026</mass>
          <inertia>
            <ixx>0.00016727</ixx>
            <ixy>-1.3787e-22</ixy>
            <ixz>-1.031e-22</ixz>
            <iyy>9.626e-05</iyy>
            <iyz>-3.3087e-21</iyz>
            <izz>9.626e-05</izz>
          </inertia>
        </inertial>
        <collision name='swerve_LW_link_collision'>
          <pose frame=''>0 0 0 0 -0 0</pose>
          <geometry>
            <mesh>
              <scale>1 1 1</scale>
              <uri>/home/swerve/Swerve/swerve_ws/src/swerve/swerve_description/meshes/wheel.stl</uri>
            </mesh>
          </geometry>
          <max_contacts>10</max_contacts>
          <surface>
            <contact>
              <ode/>
            </contact>
            <bounce/>
            <friction>
              <torsional>
                <ode/>
              </torsional>
              <ode/>
            </friction>
          </surface>
        </collision>
        <visual name='swerve_LW_link_visual'>
          <pose frame=''>0 0 0 0 -0 0</pose>
          <geometry>
            <mesh>
              <scale>1 1 1</scale>
              <uri>/home/swerve/Swerve/swerve_ws/src/swerve/swerve_description/meshes/wheel.stl</uri>
            </mesh>
          </geometry>
        </visual>
        <self_collide>0</self_collide>
        <kinematic>0</kinematic>
        <gravity>1</gravity>
      </link>
      <joint name='swerve_joint_LW' type='revolute'>
        <child>swerve_LW_link</child>
        <parent>swerve_LS_link</parent>
        <axis>
          <xyz>4e-06 1 0</xyz>
          <limit>
            <lower>-1e+16</lower>
            <upper>1e+16</upper>
          </limit>
          <dynamics>
            <spring_reference>0</spring_reference>
            <spring_stiffness>0</spring_stiffness>
          </dynamics>
          <use_parent_model_frame>1</use_parent_model_frame>
        </axis>
      </joint>
      <link name='swerve_RS_link'>
        <pose frame=''>-0.190501 -0.329959 0.17 1.5708 0 -1.5708</pose>
        <inertial>
          <pose frame=''>-0 -0.062713 -0 0 -0 0</pose>
          <mass>0.449039</mass>
          <inertia>
            <ixx>0.0010313</ixx>
            <ixy>1.377e-13</ixy>
            <ixz>1.6475e-20</ixz>
            <iyy>0.00038801</iyy>
            <iyz>2.1123e-20</iyz>
            <izz>0.001103</izz>
          </inertia>
        </inertial>
        <collision name='swerve_RS_link_collision'>
          <pose frame=''>0 0 0 0 -0 0</pose>
          <geometry>
            <mesh>
              <scale>1 1 1</scale>
              <uri>/home/swerve/Swerve/swerve_ws/src/swerve/swerve_description/meshes/swivel.stl</uri>
            </mesh>
          </geometry>
          <max_contacts>10</max_contacts>
          <surface>
            <contact>
              <ode/>
            </contact>
            <bounce/>
            <friction>
              <torsional>
                <ode/>
              </torsional>
              <ode/>
            </friction>
          </surface>
        </collision>
        <visual name='swerve_RS_link_visual'>
          <pose frame=''>0 0 0 0 -0 0</pose>
          <geometry>
            <mesh>
              <scale>1 1 1</scale>
              <uri>/home/swerve/Swerve/swerve_ws/src/swerve/swerve_description/meshes/swivel.stl</uri>
            </mesh>
          </geometry>
        </visual>
        <self_collide>0</self_collide>
        <kinematic>0</kinematic>
        <gravity>1</gravity>
      </link>
      <joint name='swerve_joint_RS' type='revolute'>
        <child>swerve_RS_link</child>
        <parent>odom</parent>
        <axis>
          <xyz>4e-06 0 -1</xyz>
          <limit>
            <lower>-1e+16</lower>
            <upper>1e+16</upper>
          </limit>
          <dynamics>
            <spring_reference>0</spring_reference>
            <spring_stiffness>0</spring_stiffness>
          </dynamics>
          <use_parent_model_frame>1</use_parent_model_frame>
        </axis>
      </joint>
      <link name='swerve_RW_link'>
        <pose frame=''>-0.190501 -0.329959 0.043 1.5708 0 -1.5708</pose>
        <inertial>
          <pose frame=''>-0 0 -0 0 -0 0</pose>
          <mass>0.15026</mass>
          <inertia>
            <ixx>0.00016727</ixx>
            <ixy>-1.3787e-22</ixy>
            <ixz>-1.031e-22</ixz>
            <iyy>9.626e-05</iyy>
            <iyz>-3.3087e-21</iyz>
            <izz>9.626e-05</izz>
          </inertia>
        </inertial>
        <collision name='swerve_RW_link_collision'>
          <pose frame=''>0 0 0 0 -0 0</pose>
          <geometry>
            <mesh>
              <scale>1 1 1</scale>
              <uri>/home/swerve/Swerve/swerve_ws/src/swerve/swerve_description/meshes/wheel.stl</uri>
            </mesh>
          </geometry>
          <max_contacts>10</max_contacts>
          <surface>
            <contact>
              <ode/>
            </contact>
            <bounce/>
            <friction>
              <torsional>
                <ode/>
              </torsional>
              <ode/>
            </friction>
          </surface>
        </collision>
        <visual name='swerve_RW_link_visual'>
          <pose frame=''>0 0 0 0 -0 0</pose>
          <geometry>
            <mesh>
              <scale>1 1 1</scale>
              <uri>/home/swerve/Swerve/swerve_ws/src/swerve/swerve_description/meshes/wheel.stl</uri>
            </mesh>
          </geometry>
        </visual>
        <self_collide>0</self_collide>
        <kinematic>0</kinematic>
        <gravity>1</gravity>
      </link>
      <joint name='swerve_joint_RW' type='revolute'>
        <child>swerve_RW_link</child>
        <parent>swerve_RS_link</parent>
        <axis>
          <xyz>4e-06 1 0</xyz>
          <limit>
            <lower>-1e+16</lower>
            <upper>1e+16</upper>
          </limit>
          <dynamics>
            <spring_reference>0</spring_reference>
            <spring_stiffness>0</spring_stiffness>
          </dynamics>
          <use_parent_model_frame>1</use_parent_model_frame>
        </axis>
      </joint>
      <static>0</static>
      <plugin name='gazebo_ros_controller' filename='libgazebo_ros_control.so'>
        <robotNamespace>/swerve</robotNamespace>
      </plugin>
      <plugin name='p3d_base_controller' filename='libgazebo_ros_p3d.so'>
        <alwaysOn>true</alwaysOn>
        <updateRate>50.0</updateRate>
        <bodyName>odom</bodyName>
        <topicName>odom</topicName>
        <gaussianNoise>0.01</gaussianNoise>
        <frameName>world</frameName>
        <xyzOffsets>0 0 0</xyzOffsets>
        <rpyOffsets>0 0 0</rpyOffsets>
        <robotNamespace>/</robotNamespace>
      </plugin>
      <pose frame=''>0 0 0 0 -0 0</pose>
    </model>
    <model name='House 1'>
      <static>1</static>
      <link name='link'>
        <collision name='collision'>
          <geometry>
            <mesh>
              <uri>model://house_1/meshes/house_1.dae</uri>
              <scale>1 1 1</scale>
            </mesh>
          </geometry>
          <max_contacts>10</max_contacts>
          <surface>
            <contact>
              <ode/>
            </contact>
            <bounce/>
            <friction>
              <torsional>
                <ode/>
              </torsional>
              <ode/>
            </friction>
          </surface>
        </collision>
        <visual name='visual'>
          <geometry>
            <mesh>
              <uri>model://house_1/meshes/house_1.dae</uri>
              <scale>1 1 1</scale>
            </mesh>
          </geometry>
          <material>
            <script>
              <uri>model://house_1/materials/scripts</uri>
              <uri>model://house_1/materials/textures</uri>
              <name>House_1/Diffuse</name>
            </script>
            <shader type='normal_map_object_space'>
              <normal_map>House_1_Normal.png</normal_map>
            </shader>
          </material>
        </visual>
        <self_collide>0</self_collide>
        <kinematic>0</kinematic>
        <gravity>1</gravity>
      </link>
      <pose frame=''>6.32349 -7.58662 0 0 -0 0</pose>
    </model>
    <model name='House 2'>
      <static>1</static>
      <link name='link'>
        <collision name='collision'>
          <geometry>
            <mesh>
              <uri>model://house_2/meshes/house_2.dae</uri>
              <scale>1 1 1</scale>
            </mesh>
          </geometry>
          <max_contacts>10</max_contacts>
          <surface>
            <contact>
              <ode/>
            </contact>
            <bounce/>
            <friction>
              <torsional>
                <ode/>
              </torsional>
              <ode/>
            </friction>
          </surface>
        </collision>
        <visual name='visual'>
          <geometry>
            <mesh>
              <uri>model://house_2/meshes/house_2.dae</uri>
              <scale>1 1 1</scale>
            </mesh>
          </geometry>
          <material>
            <script>
              <uri>model://house_2/materials/scripts</uri>
              <uri>model://house_2/materials/textures</uri>
              <name>House_2/Diffuse</name>
            </script>
          </material>
        </visual>
        <self_collide>0</self_collide>
        <kinematic>0</kinematic>
        <gravity>1</gravity>
      </link>
      <pose frame=''>15.3304 -8.84286 0 0 -0 0</pose>
    </model>
    <model name='House 3'>
      <static>1</static>
      <link name='link'>
        <collision name='collision'>
          <geometry>
            <mesh>
              <uri>model://house_3/meshes/house_3.dae</uri>
              <scale>1 1 1</scale>
            </mesh>
          </geometry>
          <max_contacts>10</max_contacts>
          <surface>
            <contact>
              <ode/>
            </contact>
            <bounce/>
            <friction>
              <torsional>
                <ode/>
              </torsional>
              <ode/>
            </friction>
          </surface>
        </collision>
        <visual name='visual'>
          <geometry>
            <mesh>
              <uri>model://house_3/meshes/house_3.dae</uri>
              <scale>1 1 1</scale>
            </mesh>
          </geometry>
          <material>
            <script>
              <uri>model://house_3/materials/scripts</uri>
              <uri>model://house_3/materials/textures</uri>
              <name>House_3/Diffuse</name>
            </script>
          </material>
        </visual>
        <self_collide>0</self_collide>
        <kinematic>0</kinematic>
        <gravity>1</gravity>
      </link>
      <pose frame=''>26.5548 -8.88395 0 0 -0 0</pose>
    </model>
    <model name='Gas Station'>
      <static>1</static>
      <link name='link'>
        <pose frame=''>0 0 0 0 -0 0</pose>
        <collision name='collision'>
          <geometry>
            <mesh>
              <uri>model://gas_station/meshes/gas_station.dae</uri>
              <scale>1 1 1</scale>
            </mesh>
          </geometry>
          <max_contacts>10</max_contacts>
          <surface>
            <contact>
              <ode/>
            </contact>
            <bounce/>
            <friction>
              <torsional>
                <ode/>
              </torsional>
              <ode/>
            </friction>
          </surface>
        </collision>
        <visual name='visual'>
          <geometry>
            <mesh>
              <uri>model://gas_station/meshes/gas_station.dae</uri>
              <scale>1 1 1</scale>
            </mesh>
          </geometry>
          <material>
            <script>
              <uri>model://gas_station/materials/scripts</uri>
              <uri>model://gas_station/materials/textures</uri>
              <name>GasStation/Diffuse</name>
            </script>
            <shader type='normal_map_object_space'>
              <normal_map>GasStation_Normal.png</normal_map>
            </shader>
          </material>
        </visual>
        <self_collide>0</self_collide>
        <kinematic>0</kinematic>
        <gravity>1</gravity>
      </link>
      <pose frame=''>4.2775 33.6828 0 0 -0 0</pose>
    </model>
    <state world_name='default'>
      <sim_time>56 732000000</sim_time>
      <real_time>60 882712278</real_time>
      <wall_time>1511738979 808609280</wall_time>
      <iterations>56732</iterations>
      <model name='Gas Station'>
        <pose frame=''>4.2775 33.6828 0 0 -0 0</pose>
        <scale>1 1 1</scale>
        <link name='link'>
          <pose frame=''>4.2775 33.6828 0 0 -0 0</pose>
          <velocity>0 0 0 0 -0 0</velocity>
          <acceleration>0 0 0 0 -0 0</acceleration>
          <wrench>0 0 0 0 -0 0</wrench>
        </link>
      </model>
      <model name='House 1'>
        <pose frame=''>6.32349 -7.58662 0 0 -0 0</pose>
        <scale>1 1 1</scale>
        <link name='link'>
          <pose frame=''>6.32349 -7.58662 0 0 -0 0</pose>
          <velocity>0 0 0 0 -0 0</velocity>
          <acceleration>0 0 0 0 -0 0</acceleration>
          <wrench>0 0 0 0 -0 0</wrench>
        </link>
      </model>
      <model name='House 2'>
        <pose frame=''>15.3304 -8.84286 0 0 -0 0</pose>
        <scale>1 1 1</scale>
        <link name='link'>
          <pose frame=''>15.3304 -8.84286 0 0 -0 0</pose>
          <velocity>0 0 0 0 -0 0</velocity>
          <acceleration>0 0 0 0 -0 0</acceleration>
          <wrench>0 0 0 0 -0 0</wrench>
        </link>
      </model>
      <model name='House 3'>
        <pose frame=''>26.5548 -8.88395 0 0 -0 0</pose>
        <scale>1 1 1</scale>
        <link name='link'>
          <pose frame=''>26.5548 -8.88395 0 0 -0 0</pose>
          <velocity>0 0 0 0 -0 0</velocity>
          <acceleration>0 0 0 0 -0 0</acceleration>
          <wrench>0 0 0 0 -0 0</wrench>
        </link>
      </model>
      <model name='ground_plane'>
        <pose frame=''>0 0 0 0 -0 0</pose>
        <scale>1 1 1</scale>
        <link name='link'>
          <pose frame=''>0 0 0 0 -0 0</pose>
          <velocity>0 0 0 0 -0 0</velocity>
          <acceleration>0 0 0 0 -0 0</acceleration>
          <wrench>0 0 0 0 -0 0</wrench>
        </link>
      </model>
      <model name='swerve'>
        <pose frame=''>-0.004164 -0.00566 0.001353 -7.9e-05 -0.000205 -0.000638</pose>
        <scale>1 1 1</scale>
        <link name='odom'>
          <pose frame=''>-0.004164 -0.00566 0.001353 -7.9e-05 -0.000205 -0.000638</pose>
          <velocity>0.000412 -0.000504 -0.009475 0.000834 0.000233 -0.000453</velocity>
          <acceleration>-0.021807 0.020609 -9.77114 -0.012594 -0.029297 0.043929</acceleration>
          <wrench>-0.152782 0.144389 -68.4586 0 -0 0</wrench>
        </link>
        <link name='swerve_FS_link'>
          <pose frame=''>0.376801 -0.005891 0.171431 1.571 -7.7e-05 -1.57022</pose>
          <velocity>0.000483 -0.000785 -0.009674 0.000266 -0.000284 -0.000453</velocity>
          <acceleration>0.049331 -0.060287 -9.89185 -1.06542 -0.227858 -0.545453</acceleration>
          <wrench>0.022151 -0.027071 -4.44183 0 -0 0</wrench>
        </link>
        <link name='swerve_FW_link'>
          <pose frame=''>0.376826 -0.005902 0.044432 1.30294 -5.5e-05 -1.57022</pose>
          <velocity>0.000552 -0.000587 -0.009977 -0.005039 -0.000287 -0.000806</velocity>
          <acceleration>0.213023 -0.125982 -10.2611 1.47224 0.612653 -1.20654</acceleration>
          <wrench>0.032009 -0.01893 -1.54183 0 -0 0</wrench>
        </link>
        <link name='swerve_LS_link'>
          <pose frame=''>-0.194487 0.324435 0.171288 1.571 -7.8e-05 -1.57405</pose>
          <velocity>0.000598 -0.000495 -0.009283 0.000743 0.000353 -0.000453</velocity>
          <acceleration>0.062423 -0.075675 -9.8029 -0.631752 -0.356319 -0.746239</acceleration>
          <wrench>0.02803 -0.033981 -4.40188 0 -0 0</wrench>
        </link>
        <link name='swerve_LW_link'>
          <pose frame=''>-0.194461 0.324425 0.04429 1.73612 -5.6e-05 -1.57405</pose>
          <velocity>0.000589 -0.000268 -0.009612 -0.004829 0.000371 -0.001144</velocity>
          <acceleration>0.240551 -0.162926 -9.85701 -2.87291 0.420965 -1.18014</acceleration>
          <wrench>0.036145 -0.024481 -1.48111 0 -0 0</wrench>
        </link>
        <link name='swerve_RS_link'>
          <pose frame=''>-0.194911 -0.335484 0.171339 1.571 -7.9e-05 -1.57297</pose>
          <velocity>0.000331 -0.000583 -0.009668 0.000906 0.000303 -0.000453</velocity>
          <acceleration>0.041295 -0.082986 -9.7076 0.437882 0.038311 0.230443</acceleration>
          <wrench>0.018543 -0.037264 -4.35909 0 -0 0</wrench>
        </link>
        <link name='swerve_RW_link'>
          <pose frame=''>-0.194885 -0.335495 0.044341 1.752 -4.5e-05 -1.57297</pose>
          <velocity>0.000318 -0.000322 -0.010162 -0.007563 0.000321 -0.00077</velocity>
          <acceleration>0.10584 -0.017711 -10.6206 2.98756 -0.828717 1.39173</acceleration>
          <wrench>0.015904 -0.002661 -1.59585 0 -0 0</wrench>
        </link>
      </model>
      <light name='sun'>
        <pose frame=''>0 0 10 0 -0 0</pose>
      </light>
    </state>
  </world>
</sdf>
