<?xml version="1.0" ?>
<!-- =================================================================================== -->
<!-- |    This document was autogenerated by xacro from /home/freddy/Workspaces/swerve_ws/src/swerve/swerve_description/robots/swerve.urdf.xacro | -->
<!-- |    EDITING THIS FILE BY HAND IS NOT RECOMMENDED                                 | -->
<!-- =================================================================================== -->
<!-- 
Highest level XACRO file for the swerve robot
Author: Frederick Wachter - wachterfreddy@gmail.com
Created: 2017-07-15
-->
<robot name="swerve" xmlns:xacro="http://www.ros.org/wiki/xacro">
  <!-- 
    IMPORTS 
  -->
  <!-- Import constants and modeling macros -->
  <!-- Common geometry properties -->
  <!-- Color properties -->
  <!-- Common visual and collision properties -->
  <!-- Common joint properties -->
  <!-- Constants -->
  <!-- Import swerve robot -->
  <!-- Include constants and modeling macros -->
  <!-- Common geometry properties -->
  <!-- Color properties -->
  <!-- Common visual and collision properties -->
  <!-- Common joint properties -->
  <!-- Constants -->
  <!--
    WORLD DEFINITION
  -->
  <!-- Fixed dummy frame -->
  <link name="swerve_base"/>
  <!--
    MACRO DEFINITIONS
  -->
  <!-- Define macros for swerve import -->
  <!--
      DUMMY JOINT DEFINITION
    -->
  <joint name="swerve_base_joint" type="fixed">
    <origin rpy="0 0 0" xyz="0 0 0.17"/>
    <parent link="swerve_base"/>
    <child link="swerve_body"/>
  </joint>
  <!--
      CHASSIS DEFINITION
    -->
  <link name="swerve_body">
    <inertial>
      <origin rpy="0 0 0" xyz="9.6121E-17 -0.0127 -7.6853E-05"/>
      <mass value="7.0052"/>
      <inertia ixx="0.27011" ixy="1.9658E-19" ixz="1.4409E-16" iyy="0.5327" iyz="-3.5181E-19" izz="0.26334"/>
    </inertial>
    <visual>
      <origin rpy="0 0 0" xyz="0 0 0"/>
      <geometry>
        <mesh filename="package://swerve_description/meshes/chassis.stl"/>
      </geometry>
      <material name="">
        <color rgba="1 0 0 1"/>
      </material>
    </visual>
    <collision>
      <origin rpy="0 0 0" xyz="0 0 0"/>
      <geometry>
        <mesh filename="package://swerve_description/meshes/chassis.stl"/>
      </geometry>
    </collision>
  </link>
  <!--
      FRONT SWIVEL DEFINITION
    -->
  <joint name="swerve_joint_FS" type="continuous">
    <origin rpy="1.5708 0 0" xyz="0 0.381 0"/>
    <parent link="swerve_body"/>
    <child link="swerve_FS_link"/>
    <axis xyz="0 -1 0"/>
  </joint>
  <link name="swerve_FS_link">
    <inertial>
      <origin rpy="0 0 0" xyz="-5.819E-13 -0.062713 0"/>
      <mass value="0.449039"/>
      <inertia ixx="0.0010313" ixy="1.377E-13" ixz="4.6213E-21" iyy="0.00038801" iyz="-9.7714E-21" izz="0.001103"/>
    </inertial>
    <visual>
      <origin rpy="0 0 0" xyz="0 0 0"/>
      <geometry>
        <mesh filename="package://swerve_description/meshes/swivel.stl"/>
      </geometry>
      <material name="">
        <color rgba="0 1 0 1"/>
      </material>
    </visual>
    <collision>
      <origin rpy="0 0 0" xyz="0 0 0"/>
      <geometry>
        <mesh filename="package://swerve_description/meshes/swivel.stl"/>
      </geometry>
    </collision>
  </link>
  <joint name="swerve_joint_FW" type="continuous">
    <origin rpy="0 0 0" xyz="0 -0.127 0"/>
    <parent link="swerve_FS_link"/>
    <child link="swerve_FW_link"/>
    <axis xyz="-1 0 0"/>
  </joint>
  <link name="swerve_FW_link">
    <inertial>
      <origin rpy="0 0 0" xyz="-7.8185E-19 2.7756E-17 5.5511E-17"/>
      <mass value="0.15026"/>
      <inertia ixx="0.00016727" ixy="-4.9394E-22" ixz="-2.3462E-22" iyy="9.626E-05" iyz="-1.4682E-20" izz="9.626E-05"/>
    </inertial>
    <visual>
      <origin rpy="0 0 0" xyz="0 0 0"/>
      <geometry>
        <mesh filename="package://swerve_description/meshes/wheel.stl"/>
      </geometry>
      <material name="">
        <color rgba="0 0 1 1"/>
      </material>
    </visual>
    <collision>
      <origin rpy="0 0 0" xyz="0 0 0"/>
      <geometry>
        <mesh filename="package://swerve_description/meshes/wheel.stl"/>
      </geometry>
    </collision>
  </link>
  <!--
      LEFT SWIVEL DEFINITION
    -->
  <joint name="swerve_joint_LS" type="continuous">
    <origin rpy="1.5708 0 0" xyz="-0.32996 -0.1905 0"/>
    <parent link="swerve_body"/>
    <child link="swerve_LS_link"/>
    <axis xyz="0 -1 0"/>
  </joint>
  <link name="swerve_LS_link">
    <inertial>
      <origin rpy="0 0 0" xyz="-5.8187E-13 -0.062713 0"/>
      <mass value="0.449039"/>
      <inertia ixx="0.0010313" ixy="1.377E-13" ixz="1.6475E-20" iyy="0.00038801" iyz="2.1123E-20" izz="0.001103"/>
    </inertial>
    <visual>
      <origin rpy="0 0 0" xyz="0 0 0"/>
      <geometry>
        <mesh filename="package://swerve_description/meshes/swivel.stl"/>
      </geometry>
      <material name="">
        <color rgba="0 1 0 1"/>
      </material>
    </visual>
    <collision>
      <origin rpy="0 0 0" xyz="0 0 0"/>
      <geometry>
        <mesh filename="package://swerve_description/meshes/swivel.stl"/>
      </geometry>
    </collision>
  </link>
  <joint name="swerve_joint_LW" type="continuous">
    <origin rpy="0 0 0" xyz="0 -0.127 0"/>
    <parent link="swerve_LS_link"/>
    <child link="swerve_LW_link"/>
    <axis xyz="-1 0 0"/>
  </joint>
  <link name="swerve_LW_link">
    <inertial>
      <origin rpy="0 0 0" xyz="0 2.7756E-17 0"/>
      <mass value="0.15026"/>
      <inertia ixx="0.00016727" ixy="-1.3787E-22" ixz="-1.031E-22" iyy="9.626E-05" iyz="-3.3087E-21" izz="9.626E-05"/>
    </inertial>
    <visual>
      <origin rpy="0 0 0" xyz="0 0 0"/>
      <geometry>
        <mesh filename="package://swerve_description/meshes/wheel.stl"/>
      </geometry>
      <material name="">
        <color rgba="0 0 1 1"/>
      </material>
    </visual>
    <collision>
      <origin rpy="0 0 0" xyz="0 0 0"/>
      <geometry>
        <mesh filename="package://swerve_description/meshes/wheel.stl"/>
      </geometry>
    </collision>
  </link>
  <!--
      RIGHT SWIVEL DEFINITION
    -->
  <joint name="swerve_joint_RS" type="continuous">
    <origin rpy="1.5708 0 0" xyz="0.32996 -0.1905 0"/>
    <parent link="swerve_body"/>
    <child link="swerve_RS_link"/>
    <axis xyz="0 -1 0"/>
  </joint>
  <link name="swerve_RS_link">
    <inertial>
      <origin rpy="0 0 0" xyz="-5.8192E-13 -0.062713 -2.7756E-17"/>
      <mass value="0.449039"/>
      <inertia ixx="0.0010313" ixy="1.377E-13" ixz="1.6475E-20" iyy="0.00038801" iyz="2.1123E-20" izz="0.001103"/>
    </inertial>
    <visual>
      <origin rpy="0 0 0" xyz="0 0 0"/>
      <geometry>
        <mesh filename="package://swerve_description/meshes/swivel.stl"/>
      </geometry>
      <material name="">
        <color rgba="0 1 0 1"/>
      </material>
    </visual>
    <collision>
      <origin rpy="0 0 0" xyz="0 0 0"/>
      <geometry>
        <mesh filename="package://swerve_description/meshes/swivel.stl"/>
      </geometry>
    </collision>
  </link>
  <joint name="swerve_joint_RW" type="continuous">
    <origin rpy="0 0 0" xyz="0 -0.127 0"/>
    <parent link="swerve_RS_link"/>
    <child link="swerve_RW_link"/>
    <axis xyz="-1 0 0"/>
  </joint>
  <link name="swerve_RW_link">
    <inertial>
      <origin rpy="0 0 0" xyz="-5.5511E-17 2.7756E-17 -2.7756E-17"/>
      <mass value="0.15026"/>
      <inertia ixx="0.00016727" ixy="-1.3787E-22" ixz="-1.031E-22" iyy="9.626E-05" iyz="-3.3087E-21" izz="9.626E-05"/>
    </inertial>
    <visual>
      <origin rpy="0 0 0" xyz="0 0 0"/>
      <geometry>
        <mesh filename="package://swerve_description/meshes/wheel.stl"/>
      </geometry>
      <material name="">
        <color rgba="0 0 1 1"/>
      </material>
    </visual>
    <collision>
      <origin rpy="0 0 0" xyz="0 0 0"/>
      <geometry>
        <mesh filename="package://swerve_description/meshes/wheel.stl"/>
      </geometry>
    </collision>
  </link>
</robot>
