<?xml version="1.0"?>

<!--
@file swerve_utilities.xacro
@brief Utilitiy properties for Swerve robot
@author Frederick Wachter - wachterfreddy@gmail.com
@date Created: 2017-11-05
-->

<robot name="swerve" xmlns:xacro="http://www.ros.org/wiki/xacro">

  <!-- Constants -->
  <xacro:property name="pi" value="1.5708" />
  
  <xacro:property name="chassis_mass" value="7.0052" />
  <xacro:property name="swivel_mass" value="0.449039" />
  <xacro:property name="wheel_mass" value="0.15026" />
  <xacro:property name="mechanical_reduction" value="1" />

  <!-- Common geometry properties -->
  <xacro:property name="chassis_geometry">
    <geometry>
      <mesh filename="package://swerve_description/meshes/chassis.stl" />
    </geometry>
  </xacro:property>

  <xacro:property name="swivel_geometry">
    <geometry>
      <mesh filename="package://swerve_description/meshes/swivel.stl" />
    </geometry>
  </xacro:property>

  <xacro:property name="wheel_geometry">
    <geometry>
      <mesh filename="package://swerve_description/meshes/wheel.stl" />
    </geometry>
  </xacro:property>

  <!-- Color properties -->
  <xacro:property name="color_red">
    <material name="">
      <color rgba="1 0 0 1" />
    </material>
  </xacro:property>

  <xacro:property name="color_green">
    <material name="">
      <color rgba="0 1 0 1" />
    </material>
  </xacro:property>

  <xacro:property name="color_blue">
    <material name="">
      <color rgba="0 0 1 1" />
    </material>
  </xacro:property>

  <!-- Common visual and collision properties -->
  <xacro:property name="chassis_visual_collision">
    <visual>
      <origin xyz="0 0 0" rpy="0 0 0" />
      <xacro:insert_block name="chassis_geometry" />
      <xacro:insert_block name="color_red" />
    </visual>
    <collision>
      <origin xyz="0 0 0" rpy="0 0 0" />
      <xacro:insert_block name="chassis_geometry" />
    </collision>
  </xacro:property>

  <xacro:property name="swivel_visual_collision">
    <visual>
      <origin xyz="0 0 0" rpy="0 0 0" />
      <xacro:insert_block name="swivel_geometry" />
      <xacro:insert_block name="color_green" />
    </visual>
    <collision>
      <origin xyz="0 0 0" rpy="0 0 0" />
      <xacro:insert_block name="swivel_geometry" />
    </collision>
  </xacro:property>

  <xacro:property name="wheel_visual_collision">
    <visual>
      <origin xyz="0 0 0" rpy="0 0 0" />
      <xacro:insert_block name="wheel_geometry" />
      <xacro:insert_block name="color_blue" />
    </visual>
    <collision>
      <origin xyz="0 0 0" rpy="0 0 0" />
      <xacro:insert_block name="wheel_geometry" />
    </collision>
  </xacro:property>

  <!-- Common joint properties -->
  <xacro:macro name="wheel_joint" params="joint_name parent child hardware_interface">
    <joint name="${joint_name}" type="continuous">
      <origin xyz="0 -0.127 0" rpy="0 0 0" />
      <parent link="${parent}" />
      <child link="${child}" />
      <axis xyz="-1 0 0" />
    </joint>

    <transmission name="${joint_name}_trans">
      <type>transmission_interface/SimpleTransmission</type>
      <joint name="${joint_name}">
        <hardwareInterface>hardware_interface/${hardware_interface}</hardwareInterface>
      </joint>
      <actuator name="${joint_name}_motor">
        <mechanicalReduction>${mechanical_reduction}</mechanicalReduction>
        <hardwareInterface>hardware_interface/${hardware_interface}</hardwareInterface>
      </actuator>
    </transmission>
  </xacro:macro>

  <xacro:macro name="swerve_joint" params="joint_name parent child x y hardware_interface">
    <joint name="${joint_name}" type="continuous">
      <origin xyz="${x} ${y} 0" rpy="1.5708 0 0" />
      <parent link="${parent}" />
      <child link="${child}" />
      <axis xyz="0 -1 0" />
    </joint>

    <transmission name="${joint_name}_trans">
      <type>transmission_interface/SimpleTransmission</type>
      <joint name="${joint_name}">
        <hardwareInterface>hardware_interface/${hardware_interface}</hardwareInterface>
      </joint>
      <actuator name="${joint_name}_motor">
        <mechanicalReduction>${mechanical_reduction}</mechanicalReduction>
        <hardwareInterface>hardware_interface/${hardware_interface}</hardwareInterface>
      </actuator>
    </transmission>
  </xacro:macro>

</robot>


